INFO:     Started server process [36521]
INFO:     Waiting for application startup.
INFO:     Application startup complete.
INFO:     Uvicorn running on http://0.0.0.0:8000 (Press CTRL+C to quit)
ERROR:    Traceback (most recent call last):
  File "/Users/chenzi/env/miniconda3/envs/py310/lib/python3.10/site-packages/starlette/routing.py", line 700, in lifespan
    await receive()
  File "/Users/chenzi/env/miniconda3/envs/py310/lib/python3.10/site-packages/uvicorn/lifespan/on.py", line 137, in receive
    return await self.receive_queue.get()
  File "/Users/chenzi/env/miniconda3/envs/py310/lib/python3.10/asyncio/queues.py", line 159, in get
    await getter
asyncio.exceptions.CancelledError

_GatheringFuture exception was never retrieved
future: <_GatheringFuture finished exception=CancelledError()>
Traceback (most recent call last):
  File "/Users/chenzi/env/miniconda3/envs/py310/lib/python3.10/contextlib.py", line 153, in __exit__
    self.gen.throw(typ, value, traceback)
  File "/Users/chenzi/env/miniconda3/envs/py310/lib/python3.10/site-packages/uvicorn/server.py", line 320, in capture_signals
    yield
  File "/Users/chenzi/env/miniconda3/envs/py310/lib/python3.10/site-packages/uvicorn/server.py", line 69, in serve
    await self._serve(sockets)
  File "/Users/chenzi/env/miniconda3/envs/py310/lib/python3.10/site-packages/uvicorn/server.py", line 87, in _serve
    await self.main_loop()
  File "/Users/chenzi/env/miniconda3/envs/py310/lib/python3.10/site-packages/uvicorn/server.py", line 228, in main_loop
    await asyncio.sleep(0.1)
  File "/Users/chenzi/env/miniconda3/envs/py310/lib/python3.10/asyncio/tasks.py", line 605, in sleep
    return await future
asyncio.exceptions.CancelledError

During handling of the above exception, another exception occurred:

asyncio.exceptions.CancelledError
